Workbook

Sheet 老师
A1: 2026春季浛洸镇第二小学教职工巴氏鲜奶补贴订购申请表（20份起送，特殊申请除外
A2: 本学期3月15日前订购一份赠送1本笔记本+1支花梨木圆珠笔
A3: 序号 | B3: 职工姓名 | C3: 联系电话 | D3: 订购种类（打√） | F3: 订购份数（100盒/210元） | H3: 备注
D4: 鲜奶（ ） 保质期7天 | E4: 乳酸（ ） 保质期15天 | F4: 市场原价 （3.5元/盒） | G4: 职工优惠价6折购 （2.1元/盒） | H4: 如果二个打√就各50支
A5: 1 | B5: 冯敏婷 | C5: 13533623452 | D5: ✓ | F5: 350 | G5: 210 | I5: 已收款
A6: 2 | B6: 张美婷1 | C6: 15768022371 | D6: ✔️ | F6: 350 | G6: 210 | I6: 已收款
A7: 3 | B7: 张美婷2 | C7: 15768022371 | E7: ✔️ | F7: 350 | G7: 210 | I7: 已收款
A8: 4 | B8: 张美婷3 | C8: 15768022371 | D8: ✔️ | F8: 350 | G8: 210 | I8: 已收款
A9: 5 | B9: 彭海玲 | C9: 13435298861 | E9: ✓ | F9: 350 | G9: 210 | I9: 已收款
A10: 6 | B10: 张美婷4 | C10: 15768022371 | E10: ✔️ | F10: 350 | G10: 210 | I10: 已收款
A11: 7 | B11: 陈炜宇 | C11: 13729680125 | D11: ✓ | F11: 350 | G11: 210 | I11: 已收款
A12: 8 | B12: 赖翠美 | C12: 13620583311 | E12: ✔️ | F12: 350 | G12: 210 | I12: 已收款
A13: 9 | B13: 陈房军 | C13: 15323132781 | E13: ✔ | F13: 350 | G13: 210 | I13: 已收款
A14: 10 | B14: 杨桃 | C14: 18218210258 | D14: ✔ | E14: ✔ | F14: 350 | G14: 210 | I14: 已收款
A15: 11 | B15: 谢秀云 | C15: 18820492512 | D15: ✔ | E15: ✔ | F15: 350 | G15: 210 | I15: 已收款
A16: 12 | B16: 李梓航 | C16: 18475811424 | D16: ☑️ | E16: ☑️ | F16: 350 | G16: 210 | I16: 已收款
A17: 13 | B17: 郭婷婷 | C17: 13416597880 | E17: ✔ | F17: 350 | G17: 210 | I17: 已收款
A18: 14 | B18: 张桂兰 | C18: 13431954225 | D18: ✔ | F18: 350 | G18: 210 | I18: 已收款
A19: 15 | B19: 陈勇强 | C19: 15170659052 | D19: ✓ | E19: ✓ | F19: 350 | G19: 210 | I19: 已收款
A20: 16 | B20: 谢金红1 | C20: 13680044210 | D20: ✔ | F20: 350 | G20: 210 | I20: 已收款
A21: 17 | B21: 谢金红2 | C21: 13680044210 | D21: ✔ | F21: 350 | G21: 210 | I21: 已收款
A22: 18 | B22: 陈石胡 | C22: 13926622020 | D22: ✔ | F22: 350 | G22: 210 | H22: 已收款 | I22: 已收款
A23: 19 | B23: 赖兰香 | C23: 13535056501 | D23: ✔️ | E23: ✔️ | F23: 350 | G23: 210 | I23: 已收款
A24: 20 | B24: 张美婷5 | C24: 15768022371 | E24: ✔️ | F24: 350 | G24: 210 | I24: 已收款
A25: 21 | B25: 郝秀丽 | D25: ✔️ | E25: ✔️ | F25: 350 | G25: 210 | H25: 3/12新增，已收款 | I25: 已收款
A26: 22 | B26: 朱玉琼 | D26: ✔️ | F26: 350 | G26: 210 | H26: 3/13新增 | I26: 已收款
A27: 23 | B27: 谢秀群 | C27: 15992023690 | E27: ✔️ | F27: 350 | G27: 210 | H27: 3.28新增 | I27: 已收款
A28: 24 | B28: 付玉芬1 | C28: 13727181524 | D28: ✔️ | F28: 350 | G28: 210 | H28: 3.28新增 | I28: 已收款
A29: 31 | B29: 付玉芬2 | E29: ✔️ | F29: 350 | G29: 210 | I29: 已收款
A30: 32 | B30: 刘冰琦 | C30: 13926629068 | D30: ✔️ | F30: 350 | G30: 210 | H30: 4.1新增 | I30: 已收款
A31: 33 | B31: 梁伟丽 | D31: ✔️ | F31: 350 | G31: 210 | H31: 4.1新增 | I31: 已收款
A32: 34 | F32: 350 | G32: 210
A33: 35 | F33: 350 | G33: 210
A34: 36 | F34: 350 | G34: 210
A35: 37 | F35: 350 | G35: 210
A36: 38 | F36: 350 | G36: 210
A37: 39 | F37: 350 | G37: 210
A38: 40 | F38: 350 | G38: 210
A39: 41 | F39: 350 | G39: 210
A40: 42 | F40: 350 | G40: 210
...

Sheet 领奶表
A1: 浛洸镇第二小学教师鲜奶领奶表
A2: （ ）月份（填写领取数量/盒）
A3: 序号 | B3: 姓名 | C3: 1 | D3: 2 | E3: 3 | F3: 4 | G3: 5 | H3: 6 | I3: 7 | J3: 8 | K3: 9 | L3: 10 | M3: 11 | N3: 12 | O3: 13 | P3: 14 | Q3: 15 | R3: 16 | S3: 17 | T3: 18 | U3: 19 | V3: 20 | W3: 21 | X3: 22 | Y3: 23 | Z3: 24 | AA3: 25 | AB3: 26 | AC3: 27 | AD3: 28 | AE3: 29 | AF3: 40
A4: 1
A5: 2
A6: 3
A7: 4
A8: 5
A9: 6
A10: 7
A11: 8
A12: 9

Sheet 配送汇总
A1: 浛洸镇第二小学教师鲜奶领奶表
A2: 序号 | B2: 姓名 | C2: 订购份数 | D2: 46090 | E2: 46093 | F2: 46097 | G2: 46100 | H2: 46104 | I2: 46107 | J2: 46111 | K2: 46114 | L2: 46119 | M2: 46121 | N2: 46125 | O2: 46128 | P2: 46132 | Q2: 46135 | R2: 46139 | S2: 46142 | W2: 总计 | X2: 剩余
A3: 1 | B3: 冯敏婷 | C3: 100 | D3: 3 | E3: 4 | F3: 3 | G3: 4 | H3: =SUMIF('3.23'!$C$3:C24,B3,'3.23'!$I$3:I27) -> 3 | I3: =SUMIF('3.26'!$C$3:D24,B3,'3.26'!$I$3:J27) -> 4 | J3: =SUMIF('3.30'!$C$3:E24,B3,'3.30'!$I$3:K27) -> 3 | K3: =SUMIF('4.2'!$C$3:F24,B3,'4.2'!$I$3:L27) -> 4 | L3: =SUMIF('4.7'!$C$3:G24,B3,'4.7'!$I$3:M27) -> 3 | M3: =SUMIF('4.9'!$C$3:H24,B3,'4.9'!$I$3:N27) -> 4 | N3: =SUMIF('4.13'!$C$3:I24,B3,'4.13'!$I$3:O27) -> 3 | O3: =SUMIF('4.16'!$C$3:J24,B3,'4.16'!$I$3:P27) -> 4 | P3: =SUMIF('4.20'!$C$3:K24,B3,'4.20'!$I$3:Q27) -> 3 | Q3: =SUMIF('4.23'!$C$3:L24,B3,'4.23'!$I$3:R27) -> 4 | W3: =SUM(D4:V4) -> 49 | X3: =100-W4 -> 51
A4: 2 | B4: 张美婷1 | C4: 100 | D4: 3 | E4: 4 | F4: 3 | G4: 4 | H4: =SUMIF('3.23'!$C$3:C25,B4,'3.23'!$I$3:I28) -> 3 | I4: =SUMIF('3.26'!$C$3:D25,B4,'3.26'!$I$3:J28) -> 4 | J4: =SUMIF('3.30'!$C$3:E25,B4,'3.30'!$I$3:K28) -> 3 | K4: =SUMIF('4.2'!$C$3:F25,B4,'4.2'!$I$3:L28) -> 4 | L4: =SUMIF('4.7'!$C$3:G25,B4,'4.7'!$I$3:M28) -> 3 | M4: =SUMIF('4.9'!$C$3:H25,B4,'4.9'!$I$3:N28) -> 4 | N4: =SUMIF('4.13'!$C$3:I25,B4,'4.13'!$I$3:O28) -> 3 | O4: =SUMIF('4.16'!$C$3:J25,B4,'4.16'!$I$3:P28) -> 4 | P4: =SUMIF('4.20'!$C$3:K25,B4,'4.20'!$I$3:Q28) -> 3 | Q4: =SUMIF('4.23'!$C$3:L25,B4,'4.23'!$I$3:R28) -> 4 | W4: =SUM(D4:V4) -> 49 | X4: =140-W4 -> 91 | Y4: 续订已收款
A5: 3 | B5: 张美婷2 | C5: 100 | D5: 3 | E5: 4 | F5: 3 | G5: 4 | H5: =SUMIF('3.23'!$C$3:C26,B5,'3.23'!$I$3:I29) -> 3 | I5: =SUMIF('3.26'!$C$3:D26,B5,'3.26'!$I$3:J29) -> 4 | J5: =SUMIF('3.30'!$C$3:E26,B5,'3.30'!$I$3:K29) -> 3 | K5: =SUMIF('4.2'!$C$3:F26,B5,'4.2'!$I$3:L29) -> 4 | L5: =SUMIF('4.7'!$C$3:G26,B5,'4.7'!$I$3:M29) -> 3 | M5: =SUMIF('4.9'!$C$3:H26,B5,'4.9'!$I$3:N29) -> 4 | N5: =SUMIF('4.13'!$C$3:I26,B5,'4.13'!$I$3:O29) -> 3 | O5: =SUMIF('4.16'!$C$3:J26,B5,'4.16'!$I$3:P29) -> 4 | P5: =SUMIF('4.20'!$C$3:K26,B5,'4.20'!$I$3:Q29) -> 3 | Q5: =SUMIF('4.23'!$C$3:L26,B5,'4.23'!$I$3:R29) -> 4 | W5: =SUM(D5:V5) -> 49 | X5: =140-W5 -> 91 | Y5: 续订已收款
A6: 4 | B6: 张美婷3 | C6: 100 | D6: 3 | E6: 4 | F6: 3 | G6: 4 | H6: =SUMIF('3.23'!$C$3:C27,B6,'3.23'!$I$3:I30) -> 3 | I6: =SUMIF('3.26'!$C$3:D27,B6,'3.26'!$I$3:J30) -> 4 | J6: =SUMIF('3.30'!$C$3:E27,B6,'3.30'!$I$3:K30) -> 3 | K6: =SUMIF('4.2'!$C$3:F27,B6,'4.2'!$I$3:L30) -> 4 | L6: =SUMIF('4.7'!$C$3:G27,B6,'4.7'!$I$3:M30) -> 3 | M6: =SUMIF('4.9'!$C$3:H27,B6,'4.9'!$I$3:N30) -> 4 | N6: =SUMIF('4.13'!$C$3:I27,B6,'4.13'!$I$3:O30) -> 3 | O6: =SUMIF('4.16'!$C$3:J27,B6,'4.16'!$I$3:P30) -> 4 | P6: =SUMIF('4.20'!$C$3:K27,B6,'4.20'!$I$3:Q30) -> 3 | Q6: =SUMIF('4.23'!$C$3:L27,B6,'4.23'!$I$3:R30) -> 4 | W6: =SUM(D6:V6) -> 49 | X6: =100-W6 -> 51
A7: 5 | B7: 张美婷4 | C7: 100 | D7: 3 | E7: 4 | F7: 3 | G7: 4 | H7: =SUMIF('3.23'!$C$3:C28,B7,'3.23'!$I$3:I31) -> 3 | I7: =SUMIF('3.26'!$C$3:D28,B7,'3.26'!$I$3:J31) -> 4 | J7: =SUMIF('3.30'!$C$3:E28,B7,'3.30'!$I$3:K31) -> 3 | K7: =SUMIF('4.2'!$C$3:F28,B7,'4.2'!$I$3:L31) -> 4 | L7: =SUMIF('4.7'!$C$3:G28,B7,'4.7'!$I$3:M31) -> 3 | M7: =SUMIF('4.9'!$C$3:H28,B7,'4.9'!$I$3:N31) -> 4 | N7: =SUMIF('4.13'!$C$3:I28,B7,'4.13'!$I$3:O31) -> 3 | O7: =SUMIF('4.16'!$C$3:J28,B7,'4.16'!$I$3:P31) -> 4 | P7: =SUMIF('4.20'!$C$3:K28,B7,'4.20'!$I$3:Q31) -> 3 | Q7: =SUMIF('4.23'!$C$3:L28,B7,'4.23'!$I$3:R31) -> 4 | W7: =SUM(D7:V7) -> 49 | X7: =100-W7 -> 51
A8: 6 | B8: 张美婷5 | C8: 100 | D8: 0 | E8: 7 | F8: 3 | G8: 4 | H8: =SUMIF('3.23'!$C$3:C29,B8,'3.23'!$I$3:I32) -> 3 | I8: =SUMIF('3.26'!$C$3:D29,B8,'3.26'!$I$3:J32) -> 4 | J8: =SUMIF('3.30'!$C$3:E29,B8,'3.30'!$I$3:K32) -> 3 | K8: =SUMIF('4.2'!$C$3:F29,B8,'4.2'!$I$3:L32) -> 4 | L8: =SUMIF('4.7'!$C$3:G29,B8,'4.7'!$I$3:M32) -> 3 | M8: =SUMIF('4.9'!$C$3:H29,B8,'4.9'!$I$3:N32) -> 4 | N8: =SUMIF('4.13'!$C$3:I29,B8,'4.13'!$I$3:O32) -> 3 | O8: =SUMIF('4.16'!$C$3:J29,B8,'4.16'!$I$3:P32) -> 4 | P8: =SUMIF('4.20'!$C$3:K29,B8,'4.20'!$I$3:Q32) -> 3 | Q8: =SUMIF('4.23'!$C$3:L29,B8,'4.23'!$I$3:R32) -> 4 | W8: =SUM(D8:V8) -> 49 | X8: =100-W8 -> 51
A9: 7 | B9: 彭海玲 | C9: 100 | D9: 3 | E9: 4 | F9: 3 | G9: 4 | H9: =SUMIF('3.23'!$C$3:C30,B9,'3.23'!$I$3:I33) -> 3 | I9: =SUMIF('3.26'!$C$3:D30,B9,'3.26'!$I$3:J33) -> 4 | J9: =SUMIF('3.30'!$C$3:E30,B9,'3.30'!$I$3:K33) -> 3 | K9: =SUMIF('4.2'!$C$3:F30,B9,'4.2'!$I$3:L33) -> 4 | L9: =SUMIF('4.7'!$C$3:G30,B9,'4.7'!$I$3:M33) -> 3 | M9: =SUMIF('4.9'!$C$3:H30,B9,'4.9'!$I$3:N33) -> 4 | N9: =SUMIF('4.13'!$C$3:I30,B9,'4.13'!$I$3:O33) -> 3 | O9: =SUMIF('4.16'!$C$3:J30,B9,'4.16'!$I$3:P33) -> 4 | P9: =SUMIF('4.20'!$C$3:K30,B9,'4.20'!$I$3:Q33) -> 3 | Q9: =SUMIF('4.23'!$C$3:L30,B9,'4.23'!$I$3:R33) -> 4 | W9: =SUM(D9:V9) -> 49 | X9: =100-W9 -> 51
A10: 8 | B10: 陈炜宇 | C10: 100 | D10: 3 | E10: 4 | F10: 3 | G10: 4 | H10: =SUMIF('3.23'!$C$3:C31,B10,'3.23'!$I$3:I34) -> 3 | I10: =SUMIF('3.26'!$C$3:D31,B10,'3.26'!$I$3:J34) -> 4 | J10: =SUMIF('3.30'!$C$3:E31,B10,'3.30'!$I$3:K34) -> 3 | K10: =SUMIF('4.2'!$C$3:F31,B10,'4.2'!$I$3:L34) -> 4 | L10: =SUMIF('4.7'!$C$3:G31,B10,'4.7'!$I$3:M34) -> 3 | M10: =SUMIF('4.9'!$C$3:H31,B10,'4.9'!$I$3:N34) -> 4 | N10: =SUMIF('4.13'!$C$3:I31,B10,'4.13'!$I$3:O34) -> 3 | O10: =SUMIF('4.16'!$C$3:J31,B10,'4.16'!$I$3:P34) -> 4 | P10: =SUMIF('4.20'!$C$3:K31,B10,'4.20'!$I$3:Q34) -> 3 | Q10: =SUMIF('4.23'!$C$3:L31,B10,'4.23'!$I$3:R34) -> 4 | W10: =SUM(D10:V10) -> 49 | X10: =140-W10 -> 91
A11: 9 | B11: 赖翠美 | C11: 100 | D11: 3 | E11: 4 | F11: 3 | G11: 4 | H11: =SUMIF('3.23'!$C$3:C32,B11,'3.23'!$I$3:I35) -> 3 | I11: =SUMIF('3.26'!$C$3:D32,B11,'3.26'!$I$3:J35) -> 4 | J11: =SUMIF('3.30'!$C$3:E32,B11,'3.30'!$I$3:K35) -> 3 | K11: =SUMIF('4.2'!$C$3:F32,B11,'4.2'!$I$3:L35) -> 4 | L11: =SUMIF('4.7'!$C$3:G32,B11,'4.7'!$I$3:M35) -> 3 | M11: =SUMIF('4.9'!$C$3:H32,B11,'4.9'!$I$3:N35) -> 4 | N11: =SUMIF('4.13'!$C$3:I32,B11,'4.13'!$I$3:O35) -> 3 | O11: =SUMIF('4.16'!$C$3:J32,B11,'4.16'!$I$3:P35) -> 4 | P11: =SUMIF('4.20'!$C$3:K32,B11,'4.20'!$I$3:Q35) -> 3 | Q11: =SUMIF('4.23'!$C$3:L32,B11,'4.23'!$I$3:R35) -> 4 | W11: =SUM(D11:V11) -> 49 | X11: =100-W11 -> 51
A12: 10 | B12: 陈房军 | C12: 100 | D12: 3 | E12: 4 | F12: 3 | G12: 4 | H12: =SUMIF('3.23'!$C$3:C33,B12,'3.23'!$I$3:I36) -> 3 | I12: =SUMIF('3.26'!$C$3:D33,B12,'3.26'!$I$3:J36) -> 4 | J12: =SUMIF('3.30'!$C$3:E33,B12,'3.30'!$I$3:K36) -> 3 | K12: =SUMIF('4.2'!$C$3:F33,B12,'4.2'!$I$3:L36) -> 4 | L12: =SUMIF('4.7'!$C$3:G33,B12,'4.7'!$I$3:M36) -> 3 | M12: =SUMIF('4.9'!$C$3:H33,B12,'4.9'!$I$3:N36) -> 4 | N12: =SUMIF('4.13'!$C$3:I33,B12,'4.13'!$I$3:O36) -> 3 | O12: =SUMIF('4.16'!$C$3:J33,B12,'4.16'!$I$3:P36) -> 4 | P12: =SUMIF('4.20'!$C$3:K33,B12,'4.20'!$I$3:Q36) -> 3 | Q12: =SUMIF('4.23'!$C$3:L33,B12,'4.23'!$I$3:R36) -> 4 | W12: =SUM(D12:V12) -> 49 | X12: =100-W12 -> 51
A13: 11 | B13: 杨桃 | C13: 100 | D13: 3 | E13: 4 | F13: 3 | G13: 4 | H13: =SUMIF('3.23'!$C$3:C34,B13,'3.23'!$I$3:I37) -> 3 | I13: =SUMIF('3.26'!$C$3:D34,B13,'3.26'!$I$3:J37) -> 4 | J13: =SUMIF('3.30'!$C$3:E34,B13,'3.30'!$I$3:K37) -> 3 | K13: =SUMIF('4.2'!$C$3:F34,B13,'4.2'!$I$3:L37) -> 4 | L13: =SUMIF('4.7'!$C$3:G34,B13,'4.7'!$I$3:M37) -> 3 | M13: =SUMIF('4.9'!$C$3:H34,B13,'4.9'!$I$3:N37) -> 4 | N13: =SUMIF('4.13'!$C$3:I34,B13,'4.13'!$I$3:O37) -> 3 | O13: =SUMIF('4.16'!$C$3:J34,B13,'4.16'!$I$3:P37) -> 4 | P13: =SUMIF('4.20'!$C$3:K34,B13,'4.20'!$I$3:Q37) -> 3 | Q13: =SUMIF('4.23'!$C$3:L34,B13,'4.23'!$I$3:R37) -> 4 | W13: =SUM(D13:V13) -> 49 | X13: =140-W13 -> 91 | Y13: 续订已收款
A14: 12 | B14: 谢秀云 | C14: 100 | D14: 3 | E14: 4 | F14: 3 | G14: 4 | H14: =SUMIF('3.23'!$C$3:C35,B14,'3.23'!$I$3:I38) -> 3 | I14: =SUMIF('3.26'!$C$3:D35,B14,'3.26'!$I$3:J38) -> 4 | J14: =SUMIF('3.30'!$C$3:E35,B14,'3.30'!$I$3:K38) -> 3 | K14: =SUMIF('4.2'!$C$3:F35,B14,'4.2'!$I$3:L38) -> 4 | L14: =SUMIF('4.7'!$C$3:G35,B14,'4.7'!$I$3:M38) -> 3 | M14: =SUMIF('4.9'!$C$3:H35,B14,'4.9'!$I$3:N38) -> 4 | N14: =SUMIF('4.13'!$C$3:I35,B14,'4.13'!$I$3:O38) -> 3 | O14: =SUMIF('4.16'!$C$3:J35,B14,'4.16'!$I$3:P38) -> 4 | P14: =SUMIF('4.20'!$C$3:K35,B14,'4.20'!$I$3:Q38) -> 3 | Q14: =SUMIF('4.23'!$C$3:L35,B14,'4.23'!$I$3:R38) -> 4 | W14: =SUM(D15:V15) -> 49 | X14: =100-W15 -> 51
A15: 13 | B15: 李梓航 | C15: 100 | D15: 3 | E15: 4 | F15: 3 | G15: 4 | H15: =SUMIF('3.23'!$C$3:C36,B15,'3.23'!$I$3:I39) -> 3 | I15: =SUMIF('3.26'!$C$3:D36,B15,'3.26'!$I$3:J39) -> 4 | J15: =SUMIF('3.30'!$C$3:E36,B15,'3.30'!$I$3:K39) -> 3 | K15: =SUMIF('4.2'!$C$3:F36,B15,'4.2'!$I$3:L39) -> 4 | L15: =SUMIF('4.7'!$C$3:G36,B15,'4.7'!$I$3:M39) -> 3 | M15: =SUMIF('4.9'!$C$3:H36,B15,'4.9'!$I$3:N39) -> 4 | N15: =SUMIF('4.13'!$C$3:I36,B15,'4.13'!$I$3:O39) -> 3 | O15: =SUMIF('4.16'!$C$3:J36,B15,'4.16'!$I$3:P39) -> 4 | P15: =SUMIF('4.20'!$C$3:K36,B15,'4.20'!$I$3:Q39) -> 3 | Q15: =SUMIF('4.23'!$C$3:L36,B15,'4.23'!$I$3:R39) -> 4 | W15: =SUM(D15:V15) -> 49 | X15: =100-W15 -> 51
A16: 14 | B16: 郭婷婷 | C16: 100 | D16: 3 | E16: 4 | F16: 3 | G16: 4 | H16: =SUMIF('3.23'!$C$3:C37,B16,'3.23'!$I$3:I40) -> 3 | I16: =SUMIF('3.26'!$C$3:D37,B16,'3.26'!$I$3:J40) -> 4 | J16: =SUMIF('3.30'!$C$3:E37,B16,'3.30'!$I$3:K40) -> 3 | K16: =SUMIF('4.2'!$C$3:F37,B16,'4.2'!$I$3:L40) -> 4 | L16: =SUMIF('4.7'!$C$3:G37,B16,'4.7'!$I$3:M40) -> 3 | M16: =SUMIF('4.9'!$C$3:H37,B16,'4.9'!$I$3:N40) -> 4 | N16: =SUMIF('4.13'!$C$3:I37,B16,'4.13'!$I$3:O40) -> 3 | O16: =SUMIF('4.16'!$C$3:J37,B16,'4.16'!$I$3:P40) -> 4 | P16: =SUMIF('4.20'!$C$3:K37,B16,'4.20'!$I$3:Q40) -> 3 | Q16: =SUMIF('4.23'!$C$3:L37,B16,'4.23'!$I$3:R40) -> 4 | W16: =SUM(D16:V16) -> 49 | X16: =100-W16 -> 51
A17: 15 | B17: 张桂兰 | C17: 100 | D17: 3 | E17: 4 | F17: 3 | G17: 4 | H17: =SUMIF('3.23'!$C$3:C38,B17,'3.23'!$I$3:I41) -> 3 | I17: =SUMIF('3.26'!$C$3:D38,B17,'3.26'!$I$3:J41) -> 4 | J17: =SUMIF('3.30'!$C$3:E38,B17,'3.30'!$I$3:K41) -> 3 | K17: =SUMIF('4.2'!$C$3:F38,B17,'4.2'!$I$3:L41) -> 4 | L17: =SUMIF('4.7'!$C$3:G38,B17,'4.7'!$I$3:M41) -> 3 | M17: =SUMIF('4.9'!$C$3:H38,B17,'4.9'!$I$3:N41) -> 4 | N17: =SUMIF('4.13'!$C$3:I38,B17,'4.13'!$I$3:O41) -> 3 | O17: =SUMIF('4.16'!$C$3:J38,B17,'4.16'!$I$3:P41) -> 4 | P17: =SUMIF('4.20'!$C$3:K38,B17,'4.20'!$I$3:Q41) -> 3 | Q17: =SUMIF('4.23'!$C$3:L38,B17,'4.23'!$I$3:R41) -> 4 | W17: =SUM(D17:V17) -> 49 | X17: =100-W17 -> 51
A18: 16 | B18: 陈勇强 | C18: 100 | D18: 3 | E18: 4 | F18: 3 | G18: 4 | H18: =SUMIF('3.23'!$C$3:C39,B18,'3.23'!$I$3:I42) -> 3 | I18: =SUMIF('3.26'!$C$3:D39,B18,'3.26'!$I$3:J42) -> 4 | J18: =SUMIF('3.30'!$C$3:E39,B18,'3.30'!$I$3:K42) -> 3 | K18: =SUMIF('4.2'!$C$3:F39,B18,'4.2'!$I$3:L42) -> 4 | L18: =SUMIF('4.7'!$C$3:G39,B18,'4.7'!$I$3:M42) -> 3 | M18: =SUMIF('4.9'!$C$3:H39,B18,'4.9'!$I$3:N42) -> 4 | N18: =SUMIF('4.13'!$C$3:I39,B18,'4.13'!$I$3:O42) -> 3 | O18: =SUMIF('4.16'!$C$3:J39,B18,'4.16'!$I$3:P42) -> 4 | P18: =SUMIF('4.20'!$C$3:K39,B18,'4.20'!$I$3:Q42) -> 3 | Q18: =SUMIF('4.23'!$C$3:L39,B18,'4.23'!$I$3:R42) -> 4 | W18: =SUM(D18:V18) -> 49 | X18: =100-W18 -> 51
A19: 17 | B19: 谢金红1 | C19: 100 | D19: 3 | E19: 4 | F19: 3 | G19: 4 | H19: =SUMIF('3.23'!$C$3:C40,B19,'3.23'!$I$3:I43) -> 3 | I19: =SUMIF('3.26'!$C$3:D40,B19,'3.26'!$I$3:J43) -> 4 | J19: =SUMIF('3.30'!$C$3:E40,B19,'3.30'!$I$3:K43) -> 3 | K19: =SUMIF('4.2'!$C$3:F40,B19,'4.2'!$I$3:L43) -> 4 | L19: =SUMIF('4.7'!$C$3:G40,B19,'4.7'!$I$3:M43) -> 3 | M19: =SUMIF('4.9'!$C$3:H40,B19,'4.9'!$I$3:N43) -> 4 | N19: =SUMIF('4.13'!$C$3:I40,B19,'4.13'!$I$3:O43) -> 3 | O19: =SUMIF('4.16'!$C$3:J40,B19,'4.16'!$I$3:P43) -> 4 | P19: =SUMIF('4.20'!$C$3:K40,B19,'4.20'!$I$3:Q43) -> 3 | Q19: =SUMIF('4.23'!$C$3:L40,B19,'4.23'!$I$3:R43) -> 4 | W19: =SUM(D19:V19) -> 49 | X19: =100-W19 -> 51
A20: 18 | B20: 谢金红2 | C20: 100 | D20: 3 | E20: 4 | F20: 3 | G20: 4 | H20: =SUMIF('3.23'!$C$3:C41,B20,'3.23'!$I$3:I44) -> 3 | I20: =SUMIF('3.26'!$C$3:D41,B20,'3.26'!$I$3:J44) -> 4 | J20: =SUMIF('3.30'!$C$3:E41,B20,'3.30'!$I$3:K44) -> 3 | K20: =SUMIF('4.2'!$C$3:F41,B20,'4.2'!$I$3:L44) -> 4 | L20: =SUMIF('4.7'!$C$3:G41,B20,'4.7'!$I$3:M44) -> 3 | M20: =SUMIF('4.9'!$C$3:H41,B20,'4.9'!$I$3:N44) -> 4 | N20: =SUMIF('4.13'!$C$3:I41,B20,'4.13'!$I$3:O44) -> 3 | O20: =SUMIF('4.16'!$C$3:J41,B20,'4.16'!$I$3:P44) -> 4 | P20: =SUMIF('4.20'!$C$3:K41,B20,'4.20'!$I$3:Q44) -> 3 | Q20: =SUMIF('4.23'!$C$3:L41,B20,'4.23'!$I$3:R44) -> 4 | W20: =SUM(D20:V20) -> 49 | X20: =100-W20 -> 51
A21: 19 | B21: 陈石胡 | C21: 100 | D21: 3 | E21: 4 | F21: 3 | G21: 4 | H21: =SUMIF('3.23'!$C$3:C42,B21,'3.23'!$I$3:I45) -> 3 | I21: =SUMIF('3.26'!$C$3:D42,B21,'3.26'!$I$3:J45) -> 4 | J21: =SUMIF('3.30'!$C$3:E42,B21,'3.30'!$I$3:K45) -> 3 | K21: =SUMIF('4.2'!$C$3:F42,B21,'4.2'!$I$3:L45) -> 4 | L21: =SUMIF('4.7'!$C$3:G42,B21,'4.7'!$I$3:M45) -> 3 | M21: =SUMIF('4.9'!$C$3:H42,B21,'4.9'!$I$3:N45) -> 4 | N21: =SUMIF('4.13'!$C$3:I42,B21,'4.13'!$I$3:O45) -> 3 | O21: =SUMIF('4.16'!$C$3:J42,B21,'4.16'!$I$3:P45) -> 4 | P21: =SUMIF('4.20'!$C$3:K42,B21,'4.20'!$I$3:Q45) -> 3 | Q21: =SUMIF('4.23'!$C$3:L42,B21,'4.23'!$I$3:R45) -> 4 | W21: =SUM(D21:V21) -> 49 | X21: =140-W21 -> 91 | Y21: 续订已收款
A22: 20 | B22: 赖兰香 | C22: 100 | D22: 0 | E22: 7 | F22: 3 | G22: 4 | H22: =SUMIF('3.23'!$C$3:C43,B22,'3.23'!$I$3:I46) -> 3 | I22: =SUMIF('3.26'!$C$3:D43,B22,'3.26'!$I$3:J46) -> 4 | J22: =SUMIF('3.30'!$C$3:E43,B22,'3.30'!$I$3:K46) -> 3 | K22: =SUMIF('4.2'!$C$3:F43,B22,'4.2'!$I$3:L46) -> 4 | L22: =SUMIF('4.7'!$C$3:G43,B22,'4.7'!$I$3:M46) -> 3 | M22: =SUMIF('4.9'!$C$3:H43,B22,'4.9'!$I$3:N46) -> 4 | N22: =SUMIF('4.13'!$C$3:I43,B22,'4.13'!$I$3:O46) -> 3 | O22: =SUMIF('4.16'!$C$3:J43,B22,'4.16'!$I$3:P46) -> 4 | P22: =SUMIF('4.20'!$C$3:K43,B22,'4.20'!$I$3:Q46) -> 3 | Q22: =SUMIF('4.23'!$C$3:L43,B22,'4.23'!$I$3:R46) -> 4 | W22: =SUM(D22:V22) -> 49 | X22: =140-W22 -> 91 | Y22: 续订已收款
A23: 21 | B23: 郝秀丽 | C23: 100 | D23: 0 | E23: 0 | F23: 6 | G23: 8 | H23: =SUMIF('3.23'!$C$3:C44,B23,'3.23'!$I$3:I47) -> 3 | I23: =SUMIF('3.26'!$C$3:D44,B23,'3.26'!$I$3:J47) -> 4 | J23: =SUMIF('3.30'!$C$3:E44,B23,'3.30'!$I$3:K47) -> 3 | K23: =SUMIF('4.2'!$C$3:F44,B23,'4.2'!$I$3:L47) -> 4 | L23: =SUMIF('4.7'!$C$3:G44,B23,'4.7'!$I$3:M47) -> 3 | M23: =SUMIF('4.9'!$C$3:H44,B23,'4.9'!$I$3:N47) -> 4 | N23: =SUMIF('4.13'!$C$3:I44,B23,'4.13'!$I$3:O47) -> 3 | O23: =SUMIF('4.16'!$C$3:J44,B23,'4.16'!$I$3:P47) -> 4 | P23: =SUMIF('4.20'!$C$3:K44,B23,'4.20'!$I$3:Q47) -> 3 | Q23: =SUMIF('4.23'!$C$3:L44,B23,'4.23'!$I$3:R47) -> 4 | W23: =SUM(D24:V24) -> 49 | X23: =100-W24 -> 51
A24: 22 | B24: 朱玉琼 | C24: 100 | D24: 0 | E24: 0 | F24: 6 | G24: 8 | H24: =SUMIF('3.23'!$C$3:C45,B24,'3.23'!$I$3:I48) -> 3 | I24: =SUMIF('3.26'!$C$3:D45,B24,'3.26'!$I$3:J48) -> 4 | J24: =SUMIF('3.30'!$C$3:E45,B24,'3.30'!$I$3:K48) -> 3 | K24: =SUMIF('4.2'!$C$3:F45,B24,'4.2'!$I$3:L48) -> 4 | L24: =SUMIF('4.7'!$C$3:G45,B24,'4.7'!$I$3:M48) -> 3 | M24: =SUMIF('4.9'!$C$3:H45,B24,'4.9'!$I$3:N48) -> 4 | N24: =SUMIF('4.13'!$C$3:I45,B24,'4.13'!$I$3:O48) -> 3 | O24: =SUMIF('4.16'!$C$3:J45,B24,'4.16'!$I$3:P48) -> 4 | P24: =SUMIF('4.20'!$C$3:K45,B24,'4.20'!$I$3:Q48) -> 3 | Q24: =SUMIF('4.23'!$C$3:L45,B24,'4.23'!$I$3:R48) -> 4 | W24: =SUM(D24:V24) -> 49 | X24: =100-W24 -> 51
A25: 23 | B25: 谢秀群 | C25: 100 | I25: =SUMIF('3.26'!$C$3:D46,B25,'3.26'!$I$3:J49) -> 0 | J25: =SUMIF('3.30'!$C$3:E46,B25,'3.30'!$I$3:K49) -> 0 | K25: =SUMIF('4.2'!$C$3:F46,B25,'4.2'!$I$3:L49) -> 4 | L25: =SUMIF('4.7'!$C$3:G46,B25,'4.7'!$I$3:M49) -> 3 | M25: =SUMIF('4.9'!$C$3:H46,B25,'4.9'!$I$3:N49) -> 4 | N25: =SUMIF('4.13'!$C$3:I46,B25,'4.13'!$I$3:O49) -> 3 | O25: =SUMIF('4.16'!$C$3:J46,B25,'4.16'!$I$3:P49) -> 4 | P25: =SUMIF('4.20'!$C$3:K46,B25,'4.20'!$I$3:Q49) -> 3 | Q25: =SUMIF('4.23'!$C$3:L46,B25,'4.23'!$I$3:R49) -> 4 | W25: =SUM(D25:V25) -> 25 | X25: =100-W25 -> 75 | Y25: 续订已收款
A26: 24 | B26: 付玉芬1 | C26: 100 | K26: =SUMIF('4.2'!$C$3:F47,B26,'4.2'!$I$3:L50) -> 4 | L26: =SUMIF('4.7'!$C$3:G47,B26,'4.7'!$I$3:M50) -> 3 | M26: =SUMIF('4.9'!$C$3:H47,B26,'4.9'!$I$3:N50) -> 4 | N26: =SUMIF('4.13'!$C$3:I47,B26,'4.13'!$I$3:O50) -> 3 | O26: =SUMIF('4.16'!$C$3:J47,B26,'4.16'!$I$3:P50) -> 4 | P26: =SUMIF('4.20'!$C$3:K47,B26,'4.20'!$I$3:Q50) -> 3 | Q26: =SUMIF('4.23'!$C$3:L47,B26,'4.23'!$I$3:R50) -> 4
A27: 25 | B27: 付玉芬2 | C27: 100 | K27: =SUMIF('4.2'!$C$3:F48,B27,'4.2'!$I$3:L51) -> 4 | L27: =SUMIF('4.7'!$C$3:G48,B27,'4.7'!$I$3:M51) -> 3 | M27: =SUMIF('4.9'!$C$3:H48,B27,'4.9'!$I$3:N51) -> 4 | N27: =SUMIF('4.13'!$C$3:I48,B27,'4.13'!$I$3:O51) -> 3 | O27: =SUMIF('4.16'!$C$3:J48,B27,'4.16'!$I$3:P51) -> 4 | P27: =SUMIF('4.20'!$C$3:K48,B27,'4.20'!$I$3:Q51) -> 3 | Q27: =SUMIF('4.23'!$C$3:L48,B27,'4.23'!$I$3:R51) -> 4
A28: 26 | B28: 刘冰琦 | C28: 100 | L28: =SUMIF('4.7'!$C$3:G49,B28,'4.7'!$I$3:M52) -> 3 | M28: =SUMIF('4.9'!$C$3:H49,B28,'4.9'!$I$3:N52) -> 4 | N28: =SUMIF('4.13'!$C$3:I49,B28,'4.13'!$I$3:O52) -> 3 | O28: =SUMIF('4.16'!$C$3:J49,B28,'4.16'!$I$3:P52) -> 4 | P28: =SUMIF('4.20'!$C$3:K49,B28,'4.20'!$I$3:Q52) -> 3 | Q28: =SUMIF('4.23'!$C$3:L49,B28,'4.23'!$I$3:R52) -> 4
A29: 27 | B29: 梁伟丽 | C29: 100 | L29: =SUMIF('4.7'!$C$3:G50,B29,'4.7'!$I$3:M53) -> 3 | M29: =SUMIF('4.9'!$C$3:H50,B29,'4.9'!$I$3:N53) -> 4 | N29: =SUMIF('4.13'!$C$3:I50,B29,'4.13'!$I$3:O53) -> 3 | O29: =SUMIF('4.16'!$C$3:J50,B29,'4.16'!$I$3:P53) -> 4 | P29: =SUMIF('4.20'!$C$3:K50,B29,'4.20'!$I$3:Q53) -> 3 | Q29: =SUMIF('4.23'!$C$3:L50,B29,'4.23'!$I$3:R53) -> 4
N31: =SUM(N3:N30) -> 81 | O31: =SUM(O3:O30) -> 108 | P31: =SUM(P3:P30) -> 81 | Q31: =SUM(Q3:Q30) -> 108 | R31: =SUM(R3:R30) -> 0 | S31: =SUM(S3:S30) -> 0 | T31: =SUM(T3:T30) -> 0 | U31: =SUM(U3:U30) -> 0 | V31: =SUM(V3:V30) -> 0

Sheet 签收
A1: 浛洸镇第二小学教师鲜奶赠品领取表
A2: 序号 | B2: 配送日期 | C2: 职工姓名 | D2: 礼品份数 （笔记本+笔） | E2: 签名 | F2: 备注
A3: 1 | B3: 46093 | C3: 冯敏婷 | D3: 1
A4: 2 | B4: 46093 | C4: 张美婷1 | D4: 1
A5: 3 | B5: 46093 | C5: 张美婷2 | D5: 1
A6: 4 | B6: 46093 | C6: 张美婷3 | D6: 1
A7: 5 | B7: 46093 | C7: 张美婷4 | D7: 1
A8: 6 | B8: 46093 | C8: 张美婷5 | D8: 1
A9: 7 | B9: 46093 | C9: 张美婷5 | D9: 1
A10: 8 | B10: 46093 | C10: 彭海玲 | D10: 1
A11: 9 | B11: 46093 | C11: 陈炜宇 | D11: 1
A12: 10 | B12: 46093 | C12: 赖翠美 | D12: 1
A13: 11 | B13: 46093 | C13: 陈房军 | D13: 1
A14: 12 | B14: 46093 | C14: 杨桃 | D14: 1
... A23: 21 | B23: 46093 | C23: 赖兰香 | D23: 1
C24: 郝秀丽 | D24: 1 | F24: 3.30送
C25: 朱玉琼 | D25: 1 | F25: 3.30送
D29: 23

Sheet 3.9
A1: 浛洸镇第二小学教师鲜奶领奶表
A2: 序号 | B2: 配送日期 | C2: 职工姓名 | D2: 配送天数 | E2: 鲜 | F2: 酸 | G2: 备注
A3: 1 | B3: 46090 | C3: 冯敏婷 | D3: 3天 | E3: 3
A4: 2 | B4: 46090 | C4: 张美婷1 | D4: 3天 | E4: 3
A5: 4 | B5: 46090 | C5: 张美婷2 | D5: 3天 | F5: 3
A6: 4 | B6: 46090 | C6: 张美婷4 | D6: 3天 | E6: 3
A7: 5 | B7: 46090 | C7: 张美婷4 | D7: 3天 | F7: 3
A8: 6 | B8: 46090 | C8: 彭海玲 | D8: 3天 | F8: 3
A9: 7 | B9: 46090 | C9: 陈炜宇 | D9: 3天 | E9: 3
A10: 8 | B10: 46090 | C10: 赖翠美 | D10: 3天 | F10: 3
A11: 9 | B11: 46090 | C11: 陈房军 | D11: 3天 | F11: 3
A12: 10 | B12: 46090 | C12: 杨桃 | D12: 3天 | E12: 2 | F12: 1
A13: 11 | B13: 46090 | C13: 谢秀云 | D13: 3天 | E13: 2 | F13: 1
A14: 12 | B14: 46090 | C14: 李梓航 | D14: 3天 | E14: 2 | F14: 1
A15: 14 | B15: 46090 | C15: 郭婷婷 | D15: 3天 | F15: 3
A16: 14 | B16: 46090 | C16: 张桂兰 | D16: 3天 | E16: 3
A17: 15 | B17: 46090 | C17: 陈勇强 | D17: 3天 | E17: 2 | F17: 1
A18: 16 | B18: 46090 | C18: 谢金红1 | D18: 3天 | E18: 3
A19: 17 | B19: 46090 | C19: 谢金红2 | D19: 3天 | E19: 3
A20: 18 | B20: 46090 | C20: 陈石胡 | D20: 3天 | E20: 3
A21: 19
A22: 20
A23: 21
E26: =SUM(E3:E25) -> 32 | F26: =SUM(F3:F25) -> 22

Sheet 3.12
A1: 浛洸镇第二小学教师鲜奶领奶表
A2: 序号 | B2: 配送日期 | C2: 职工姓名 | D2: 配送天数 | E2: 鲜 | F2: 酸 | G2: 备注
A3: 1 | B3: 46093 | C3: 冯敏婷 | D3: 4天 | E3: 4
A4: 2 | B4: 46093 | C4: 张美婷1 | D4: 4天 | E4: 4
A5: 3 | B5: 46093 | C5: 张美婷2 | D5: 4天 | F5: 4
A6: 4 | B6: 46093 | C6: 张美婷3 | D6: 4天 | E6: 4
A7: 5 | B7: 46093 | C7: 张美婷4 | D7: 4天 | F7: 4
A8: 6 | B8: 46093 | C8: 张美婷5 | D8: 4天 | F8: 4
A9: 7 | B9: 46093 | C9: 张美婷5 | D9: 3天 | F9: 3 | G9: 补发
A10: 8 | B10: 46093 | C10: 彭海玲 | D10: 4天 | F10: 4
A11: 9 | B11: 46093 | C11: 陈炜宇 | D11: 4天 | E11: 4
A12: 10 | B12: 46093 | C12: 赖翠美 | D12: 4天 | F12: 4
A13: 11 | B13: 46093 | C13: 陈房军 | D13: 4天 | F13: 4
A14: 12 | B14: 46093 | C14: 杨桃 | D14: 4天 | E14: 2 | F14: 2
A15: 13 | B15: 46093 | C15: 谢秀云 | D15: 4天 | E15: 2 | F15: 2
A16: 14 | B16: 46093 | C16: 李梓航 | D16: 4天 | E16: 2 | F16: 2
A17: 15 | B17: 46093 | C17: 郭婷婷 | D17: 4天 | F17: 4
A18: 16 | B18: 46093 | C18: 张桂兰 | D18: 4天 | E18: 4
A19: 17 | B19: 46093 | C19: 陈勇强 | D19: 4天 | E19: 2 | F19: 2
A20: 18 | B20: 46093 | C20: 谢金红1 | D20: 4天 | E20: 4
A21: 19 | B21: 46093 | C21: 谢金红2 | D21: 4天 | E21: 4
A22: 20 | B22: 46093 | C22: 陈石胡 | D22: 4天 | E22: 4
A23: 21 | B23: 46093 | C23: 赖兰香 | D23: 4天 | E23: 2 | F23: 2
A24: 22 | B24: 46093 | C24: 赖兰香 | D24: 3天 | E24: 2 | F24: 1 | G24: 补发
E28: =SUM(E3:E27) -> 44 | F28: =SUM(F3:F27) -> 42

Sheet 3.16
A1: 浛洸镇第二小学教师鲜奶领奶表
A2: 序号 | B2: 配送日期 | C2: 职工姓名 | D2: 配送天数 | E2: 鲜 | F2: 酸 | G2: 备注
A3: 1 | B3: 46097 | C3: 冯敏婷 | D3: 3天 | E3: 3
A4: 2 | B4: 46097 | C4: 张美婷1 | D4: 3天 | E4: 3
A5: 3 | B5: 46097 | C5: 张美婷2 | D5: 3天 | F5: 3
A6: 4 | B6: 46097 | C6: 张美婷3 | D6: 3天 | E6: 3
A7: 5 | B7: 46097 | C7: 张美婷4 | D7: 3天 | F7: 3
A8: 6 | B8: 46097 | C8: 张美婷5 | D8: 3天 | F8: 3
A9: 8 | B9: 46097 | C9: 彭海玲 | D9: 3天 | F9: 3
A10: 9 | B10: 46097 | C10: 陈炜宇 | D10: 3天 | E10: 3
A11: 10 | B11: 46097 | C11: 赖翠美 | D11: 3天 | F11: 3
A12: 11 | B12: 46097 | C12: 陈房军 | D12: 3天 | F12: 3
A13: 12 | B13: 46097 | C13: 杨桃 | D13: 3天 | E13: 2 | F13: 1
A14: 13 | B14: 46097 | C14: 谢秀云 | D14: 3天 | E14: 2 | F14: 1
A15: 14 | B15: 46097 | C15: 李梓航 | D15: 3天 | E15: 2 | F15: 1
A16: 15 | B16: 46097 | C16: 郭婷婷 | D16: 3天 | F16: 3
A17: 16 | B17: 46097 | C17: 张桂兰 | D17: 3天 | E17: 3
A18: 17 | B18: 46097 | C18: 陈勇强 | D18: 3天 | E18: 2 | F18: 1
A19: 18 | B19: 46097 | C19: 谢金红1 | D19: 3天 | E19: 3
A20: 19 | B20: 46097 | C20: 谢金红2 | D20: 3天 | E20: 3
A21: 20 | B21: 46097 | C21: 陈石胡 | D21: 3天 | E21: 3
A22: 21 | B22: 46097 | C22: 赖兰香 | D22: 3天 | E22: 2 | F22: 1
A23: 23 | B23: 46097 | C23: 郝秀丽 | D23: 3天 | E23: 2 | F23: 1
A24: 25 | B24: 46097 | C24: 朱玉琼 | D24: 3天 | E24: 3
A25: 24 | B25: 46097 | C25: 郝秀丽 | D25: 3天 | E25: 1 | F25: 2 | G25: 补发
A26: 26 | B26: 46097 | C26: 朱玉琼 | D26: 3天 | E26: 3 | G26: 补发
E28: =SUM(E3:E27) -> 43 | F28: =SUM(F3:F27) -> 29

Sheet 3.19
A1: 浛洸镇第二小学教师鲜奶领奶表
A2: 序号 | B2: 配送日期 | C2: 职工姓名 | D2: 配送天数 | E2: 鲜 | F2: 酸 | G2: 备注
A3: 1 | B3: 46100 | C3: 冯敏婷 | D3: 4天 | E3: 4
A4: 2 | B4: 46100 | C4: 张美婷1 | D4: 4天 | E4: 4
A5: 3 | B5: 46100 | C5: 张美婷2 | D5: 4天 | F5: 4
A6: 4 | B6: 46100 | C6: 张美婷3 | D6: 4天 | E6: 4
A7: 5 | B7: 46100 | C7: 张美婷4 | D7: 4天 | F7: 4
A8: 6 | B8: 46100 | C8: 张美婷5 | D8: 4天 | F8: 4
A9: 8 | B9: 46100 | C9: 彭海玲 | D9: 4天 | F9: 4
A10: 9 | B10: 46100 | C10: 陈炜宇 | D10: 4天 | E10: 4
A11: 10 | B11: 46100 | C11: 赖翠美 | D11: 4天 | F11: 4
A12: 11 | B12: 46100 | C12: 陈房军 | D12: 4天 | F12: 4
A13: 12 | B13: 46100 | C13: 杨桃 | D13: 4天 | E13: 2 | F13: 2
A14: 13 | B14: 46100 | C14: 谢秀云 | D14: 4天 | E14: 2 | F14: 2
A15: 14 | B15: 46100 | C15: 李梓航 | D15: 4天 | E15: 2 | F15: 2
A16: 15 | B16: 46100 | C16: 郭婷婷 | D16: 4天 | F16: 4
A17: 16 | B17: 46100 | C17: 张桂兰 | D17: 4天 | E17: 4
A18: 17 | B18: 46100 | C18: 陈勇强 | D18: 4天 | E18: 2 | F18: 2
A19: 18 | B19: 46100 | C19: 谢金红1 | D19: 4天 | E19: 4
A20: 19 | B20: 46100 | C20: 谢金红2 | D20: 4天 | E20: 4
A21: 20 | B21: 46100 | C21: 陈石胡 | D21: 4天 | E21: 4
A22: 21 | B22: 46100 | C22: 赖兰香 | D22: 4天 | E22: 2 | F22: 2
A23: 23 | B23: 46100 | C23: 郝秀丽 | D23: 4天 | E23: 2 | F23: 2
A24: 25 | B24: 46100 | C24: 朱玉琼 | D24: 4天 | E24: 4
A25: 24 | B25: 46100 | C25: 郝秀丽 | D25: 3天 | E25: 2 | F25: 2 | G25: 补发
A26: 26 | B26: 46100 | C26: 朱玉琼 | D26: 3天 | E26: 4 | G26: 补发
B27: 46100
E28: =SUM(E3:E27) -> 54 | F28: =SUM(F3:F27) -> 42

Sheet 3.23
A1: 浛洸镇第二小学教师鲜奶领奶表
A2: 序号 | B2: 配送日期 | C2: 职工姓名 | D2: 配送天数 | E2: 鲜 | F2: 酸 | G2: 备注
A3: 1 | B3: 46104 | C3: 冯敏婷 | D3: 3天 | E3: 3 | I3: =E3+F3 -> 3
A4: 2 | B4: 46104 | C4: 张美婷1 | D4: 3天 | E4: 3 | I4: =E4+F4 -> 3
A5: 3 | B5: 46104 | C5: 张美婷2 | D5: 3天 | F5: 3 | I5: =E5+F5 -> 3
A6: 4 | B6: 46104 | C6: 张美婷3 | D6: 3天 | E6: 3 | I6: =E6+F6 -> 3
A7: 5 | B7: 46104 | C7: 张美婷4 | D7: 3天 | F7: 3 | I7: =E7+F7 -> 3
A8: 6 | B8: 46104 | C8: 张美婷5 | D8: 3天 | F8: 3 | I8: =E8+F8 -> 3
A9: 8 | B9: 46104 | C9: 彭海玲 | D9: 3天 | F9: 3 | I9: =E9+F9 -> 3
A10: 9 | B10: 46104 | C10: 陈炜宇 | D10: 3天 | E10: 3 | I10: =E10+F10 -> 3
A11: 10 | B11: 46104 | C11: 赖翠美 | D11: 3天 | F11: 3 | I11: =E11+F11 -> 3
A12: 11 | B12: 46104 | C12: 陈房军 | D12: 3天 | F12: 3 | I12: =E12+F12 -> 3
A13: 12 | B13: 46104 | C13: 杨桃 | D13: 3天 | E13: 2 | F13: 1 | I13: =E13+F13 -> 3
A14: 13 | B14: 46104 | C14: 谢秀云 | D14: 3天 | E14: 2 | F14: 1 | I14: =E14+F14 -> 3
A15: 14 | B15: 46104 | C15: 李梓航 | D15: 3天 | E15: 2 | F15: 1 | I15: =E15+F15 -> 3
A16: 15 | B16: 46104 | C16: 郭婷婷 | D16: 3天 | F16: 3 | I16: =E16+F16 -> 3
A17: 16 | B17: 46104 | C17: 张桂兰 | D17: 3天 | E17: 3 | I17: =E17+F17 -> 3
A18: 17 | B18: 46104 | C18: 陈勇强 | D18: 3天 | E18: 2 | F18: 1 | I18: =E18+F18 -> 3
A19: 18 | B19: 46104 | C19: 谢金红1 | D19: 3天 | E19: 3 | I19: =E19+F19 -> 3
A20: 19 | B20: 46104 | C20: 谢金红2 | D20: 3天 | E20: 3 | I20: =E20+F20 -> 3
A21: 20 | B21: 46104 | C21: 陈石胡 | D21: 3天 | E21: 3 | I21: =E21+F21 -> 3
A22: 21 | B22: 46104 | C22: 赖兰香 | D22: 3天 | E22: 2 | F22: 1 | I22: =E22+F22 -> 3
A23: 23 | B23: 46104 | C23: 郝秀丽 | D23: 3天 | E23: 2 | F23: 1 | I23: =E23+F23 -> 3
A24: 25 | B24: 46104 | C24: 朱玉琼 | D24: 3天 | E24: 3 | I24: =E24+F24 -> 3
I25: =E25+F25 -> 0
I26: =E26+F26 -> 0
I27: =E27+F27 -> 0
E28: =SUM(E3:E27) -> 39 | F28: =SUM(F3:F27) -> 27 | I28: =E28+F28 -> 66

Sheet 3.26
A1: 浛洸镇第二小学教师鲜奶领奶表
A2: 序号 | B2: 配送日期 | C2: 职工姓名 | D2: 配送天数 | E2: 鲜 | F2: 酸 | G2: 备注
A3: 1 | B3: 46107 | C3: 冯敏婷 | D3: 4天 | E3: 4 | I3: =E3+F3 -> 4
A4: 2 | B4: 46107 | C4: 张美婷1 | D4: 4天 | E4: 4 | I4: =E4+F4 -> 4
A5: 3 | B5: 46107 | C5: 张美婷2 | D5: 4天 | F5: 4 | I5: =E5+F5 -> 4
A6: 4 | B6: 46107 | C6: 张美婷3 | D6: 4天 | E6: 4 | I6: =E6+F6 -> 4
A7: 5 | B7: 46107 | C7: 张美婷4 | D7: 4天 | F7: 4 | I7: =E7+F7 -> 4
A8: 6 | B8: 46107 | C8: 张美婷5 | D8: 4天 | F8: 4 | I8: =E8+F8 -> 4
A9: 7 | B9: 46107 | C9: 彭海玲 | D9: 4天 | F9: 4 | I9: =E9+F9 -> 4
A10: 8 | B10: 46107 | C10: 陈炜宇 | D10: 4天 | E10: 4 | I10: =E10+F10 -> 4
A11: 9 | B11: 46107 | C11: 赖翠美 | D11: 4天 | F11: 4 | I11: =E11+F11 -> 4
A12: 10 | B12: 46107 | C12: 陈房军 | D12: 4天 | F12: 4 | I12: =E12+F12 -> 4
A13: 11 | B13: 46107 | C13: 杨桃 | D13: 4天 | E13: 2 | F13: 2 | I13: =E13+F13 -> 4
A14: 12 | B14: 46107 | C14: 谢秀云 | D14: 4天 | E14: 2 | F14: 2 | I14: =E14+F14 -> 4
A15: 13 | B15: 46107 | C15: 李梓航 | D15: 4天 | E15: 2 | F15: 2 | I15: =E15+F15 -> 4
A16: 14 | B16: 46107 | C16: 郭婷婷 | D16: 4天 | F16: 4 | I16: =E16+F16 -> 4
A17: 15 | B17: 46107 | C17: 张桂兰 | D17: 4天 | E17: 4 | I17: =E17+F17 -> 4
A18: 16 | B18: 46107 | C18: 陈勇强 | D18: 4天 | E18: 2 | F18: 2 | I18: =E18+F18 -> 4
A19: 17 | B19: 46107 | C19: 谢金红1 | D19: 4天 | E19: 4 | I19: =E19+F19 -> 4
A20: 18 | B20: 46107 | C20: 谢金红2 | D20: 4天 | E20: 4 | I20: =E20+F20 -> 4
A21: 19 | B21: 46107 | C21: 陈石胡 | D21: 4天 | E21: 4 | I21: =E21+F21 -> 4
A22: 20 | B22: 46107 | C22: 赖兰香 | D22: 4天 | E22: 2 | F22: 2 | I22: =E22+F22 -> 4
A23: 21 | B23: 46107 | C23: 郝秀丽 | D23: 4天 | E23: 2 | F23: 2 | I23: =E23+F23 -> 4
A24: 22 | B24: 46107 | C24: 朱玉琼 | D24: 4天 | E24: 4 | I24: =E24+F24 -> 4
I25: =E25+F25 -> 0
I26: =E26+F26 -> 0
I27: =E27+F27 -> 0
E28: =SUM(E3:E27) -> 48 | F28: =SUM(F3:F27) -> 40 | I28: =E28+F28 -> 88

Sheet 3.30
A1: 浛洸镇第二小学教师鲜奶领奶表
A2: 序号 | B2: 配送日期 | C2: 职工姓名 | D2: 配送天数 | E2: 鲜 | F2: 酸 | G2: 备注
A3: 1 | B3: 46111 | C3: 冯敏婷 | D3: 3天 | E3: 3 | I3: =E3+F3 -> 3
A4: 2 | B4: 46111 | C4: 张美婷1 | D4: 3天 | E4: 3 | I4: =E4+F4 -> 3
A5: 3 | B5: 46111 | C5: 张美婷2 | D5: 3天 | F5: 3 | I5: =E5+F5 -> 3
A6: 4 | B6: 46111 | C6: 张美婷3 | D6: 3天 | E6: 3 | I6: =E6+F6 -> 3
A7: 5 | B7: 46111 | C7: 张美婷4 | D7: 3天 | F7: 3 | I7: =E7+F7 -> 3
A8: 6 | B8: 46111 | C8: 张美婷5 | D8: 3天 | F8: 3 | I8: =E8+F8 -> 3
A9: 7 | B9: 46111 | C9: 彭海玲 | D9: 3天 | F9: 3 | I9: =E9+F9 -> 3
A10: 8 | B10: 46111 | C10: 陈炜宇 | D10: 3天 | E10: 3 | I10: =E10+F10 -> 3
A11: 9 | B11: 46111 | C11: 赖翠美 | D11: 3天 | F11: 3 | I11: =E11+F11 -> 3
A12: 10 | B12: 46111 | C12: 陈房军 | D12: 3天 | F12: 3 | I12: =E12+F12 -> 3
A13: 11 | B13: 46111 | C13: 杨桃 | D13: 3天 | E13: 2 | F13: 1 | I13: =E13+F13 -> 3
A14: 12 | B14: 46111 | C14: 谢秀云 | D14: 3天 | E14: 2 | F14: 1 | I14: =E14+F14 -> 3
A15: 13 | B15: 46111 | C15: 李梓航 | D15: 3天 | E15: 2 | F15: 1 | I15: =E15+F15 -> 3
A16: 14 | B16: 46111 | C16: 郭婷婷 | D16: 3天 | F16: 3 | I16: =E16+F16 -> 3
A17: 15 | B17: 46111 | C17: 张桂兰 | D17: 3天 | E17: 3 | I17: =E17+F17 -> 3
A18: 16 | B18: 46111 | C18: 陈勇强 | D18: 3天 | E18: 2 | F18: 1 | I18: =E18+F18 -> 3
A19: 17 | B19: 46111 | C19: 谢金红1 | D19: 3天 | E19: 3 | I19: =E19+F19 -> 3
A20: 18 | B20: 46111 | C20: 谢金红2 | D20: 3天 | E20: 3 | I20: =E20+F20 -> 3
A21: 19 | B21: 46111 | C21: 陈石胡 | D21: 3天 | E21: 3 | I21: =E21+F21 -> 3
A22: 20 | B22: 46111 | C22: 赖兰香 | D22: 3天 | E22: 2 | F22: 1 | I22: =E22+F22 -> 3
A23: 21 | B23: 46111 | C23: 郝秀丽 | D23: 3天 | E23: 2 | F23: 1 | I23: =E23+F23 -> 3
A24: 22 | B24: 46111 | C24: 朱玉琼 | D24: 3天 | E24: 3 | I24: =E24+F24 -> 3
I25: =E25+F25 -> 0
I26: =E26+F26 -> 0
E27: =SUM(E3:E26) -> 39 | F27: =SUM(F3:F26) -> 27 | I27: =E27+F27 -> 66
B29: 46114 | C29: 谢秀群 | D29: 4天 | F29: 4
B30: 46114 | C30: 付玉芬1 | D30: 4天 | E30: 4
B31: 46114 | C31: 付玉芬2 | D31: 4天 | F31: 4

Sheet 4.2
A1: 浛洸镇第二小学教师鲜奶领奶表
A2: 序号 | B2: 配送日期 | C2: 职工姓名 | D2: 配送天数 | E2: 鲜 | F2: 酸 | G2: 备注
A3: 1 | B3: 46114 | C3: 冯敏婷 | D3: 4天 | E3: 4 | I3: =E3+F3 -> 4
A4: 2 | B4: 46114 | C4: 张美婷1 | D4: 4天 | E4: 4 | I4: =E4+F4 -> 4
A5: 3 | B5: 46114 | C5: 张美婷2 | D5: 4天 | F5: 4 | I5: =E5+F5 -> 4
A6: 4 | B6: 46114 | C6: 张美婷3 | D6: 4天 | E6: 4 | I6: =E6+F6 -> 4
A7: 5 | B7: 46114 | C7: 张美婷4 | D7: 4天 | F7: 4 | I7: =E7+F7 -> 4
A8: 6 | B8: 46114 | C8: 张美婷5 | D8: 4天 | F8: 4 | I8: =E8+F8 -> 4
A9: 7 | B9: 46114 | C9: 彭海玲 | D9: 4天 | F9: 4 | I9: =E9+F9 -> 4
A10: 8 | B10: 46114 | C10: 陈炜宇 | D10: 4天 | E10: 4 | I10: =E10+F10 -> 4
A11: 9 | B11: 46114 | C11: 赖翠美 | D11: 4天 | F11: 4 | I11: =E11+F11 -> 4
A12: 10 | B12: 46114 | C12: 陈房军 | D12: 4天 | F12: 4 | I12: =E12+F12 -> 4
A13: 11 | B13: 46114 | C13: 杨桃 | D13: 4天 | E13: 2 | F13: 2 | I13: =E13+F13 -> 4
A14: 12 | B14: 46114 | C14: 谢秀云 | D14: 4天 | E14: 2 | F14: 2 | I14: =E14+F14 -> 4
A15: 13 | B15: 46114 | C15: 李梓航 | D15: 4天 | E15: 2 | F15: 2 | I15: =E15+F15 -> 4
A16: 14 | B16: 46114 | C16: 郭婷婷 | D16: 4天 | F16: 4 | I16: =E16+F16 -> 4
A17: 15 | B17: 46114 | C17: 张桂兰 | D17: 4天 | E17: 4 | I17: =E17+F17 -> 4
A18: 16 | B18: 46114 | C18: 陈勇强 | D18: 4天 | E18: 2 | F18: 2 | I18: =E18+F18 -> 4
A19: 17 | B19: 46114 | C19: 谢金红1 | D19: 4天 | E19: 4 | I19: =E19+F19 -> 4
A20: 18 | B20: 46114 | C20: 谢金红2 | D20: 4天 | E20: 4 | I20: =E20+F20 -> 4
A21: 19 | B21: 46114 | C21: 陈石胡 | D21: 4天 | E21: 4 | I21: =E21+F21 -> 4
A22: 20 | B22: 46114 | C22: 赖兰香 | D22: 4天 | E22: 2 | F22: 2 | I22: =E22+F22 -> 4
A23: 21 | B23: 46114 | C23: 郝秀丽 | D23: 4天 | E23: 2 | F23: 2 | I23: =E23+F23 -> 4
A24: 22 | B24: 46114 | C24: 朱玉琼 | D24: 4天 | E24: 4 | I24: =E24+F24 -> 4
A25: 23 | B25: 46114 | C25: 谢秀群 | D25: 4天 | F25: 4 | I25: =E25+F25 -> 4
A26: 24 | B26: 46114 | C26: 付玉芬1 | D26: 4天 | E26: 4 | I26: =E26+F26 -> 4
A27: 25 | B27: 46114 | C27: 付玉芬2 | D27: 4天 | F27: 4 | I27: =E27+F27 -> 4
C28: 刘冰琦 | I28: =E28+F28 -> 0
C29: 梁伟丽 | I29: =E29+F29 -> 0
I30: =E30+F30 -> 0
E31: =SUM(E3:E30) -> 52 | F31: =SUM(F3:F30) -> 48 | I31: =E31+F31 -> 100

Sheet 4.7
A1: 浛洸镇第二小学教师鲜奶领奶表
A2: 序号 | B2: 配送日期 | C2: 职工姓名 | D2: 配送天数 | E2: 鲜 | F2: 酸 | G2: 备注
A3: 1 | B3: 46119 | C3: 冯敏婷 | D3: 3天 | E3: 3 | I3: =E3+F3 -> 3
A4: 2 | B4: 46119 | C4: 张美婷1 | D4: 3天 | E4: 3 | I4: =E4+F4 -> 3
A5: 3 | B5: 46119 | C5: 张美婷2 | D5: 3天 | F5: 3 | I5: =E5+F5 -> 3
A6: 4 | B6: 46119 | C6: 张美婷3 | D6: 3天 | E6: 3 | I6: =E6+F6 -> 3
A7: 5 | B7: 46119 | C7: 张美婷4 | D7: 3天 | F7: 3 | I7: =E7+F7 -> 3
A8: 6 | B8: 46119 | C8: 张美婷5 | D8: 3天 | F8: 3 | I8: =E8+F8 -> 3
A9: 7 | B9: 46119 | C9: 彭海玲 | D9: 3天 | F9: 3 | I9: =E9+F9 -> 3
A10: 8 | B10: 46119 | C10: 陈炜宇 | D10: 3天 | E10: 3 | I10: =E10+F10 -> 3
A11: 9 | B11: 46119 | C11: 赖翠美 | D11: 3天 | F11: 3 | I11: =E11+F11 -> 3
A12: 10 | B12: 46119 | C12: 陈房军 | D12: 3天 | F12: 3 | I12: =E12+F12 -> 3
A13: 11 | B13: 46119 | C13: 杨桃 | D13: 3天 | E13: 2 | F13: 1 | I13: =E13+F13 -> 3
A14: 12 | B14: 46119 | C14: 谢秀云 | D14: 3天 | E14: 2 | F14: 1 | I14: =E14+F14 -> 3
A15: 13 | B15: 46119 | C15: 李梓航 | D15: 3天 | E15: 2 | F15: 1 | I15: =E15+F15 -> 3
A16: 14 | B16: 46119 | C16: 郭婷婷 | D16: 3天 | F16: 3 | I16: =E16+F16 -> 3
A17: 15 | B17: 46119 | C17: 张桂兰 | D17: 3天 | E17: 3 | I17: =E17+F17 -> 3
A18: 16 | B18: 46119 | C18: 陈勇强 | D18: 3天 | E18: 2 | F18: 1 | I18: =E18+F18 -> 3
A19: 17 | B19: 46119 | C19: 谢金红1 | D19: 3天 | E19: 3 | I19: =E19+F19 -> 3
A20: 18 | B20: 46119 | C20: 谢金红2 | D20: 3天 | E20: 3 | I20: =E20+F20 -> 3
A21: 19 | B21: 46119 | C21: 陈石胡 | D21: 3天 | E21: 3 | I21: =E21+F21 -> 3
A22: 20 | B22: 46119 | C22: 赖兰香 | D22: 3天 | E22: 2 | F22: 1 | I22: =E22+F22 -> 3
A23: 21 | B23: 46119 | C23: 郝秀丽 | D23: 3天 | E23: 2 | F23: 1 | I23: =E23+F23 -> 3
A24: 22 | B24: 46119 | C24: 朱玉琼 | D24: 3天 | E24: 3 | I24: =E24+F24 -> 3
A25: 23 | B25: 46119 | C25: 谢秀群 | D25: 3天 | F25: 3 | I25: =E25+F25 -> 3
A26: 24 | B26: 46119 | C26: 付玉芬1 | D26: 3天 | E26: 3 | I26: =E26+F26 -> 3
A27: 25 | B27: 46119 | C27: 付玉芬2 | D27: 3天 | F27: 3 | I27: =E27+F27 -> 3
A28: 26 | B28: 46119 | C28: 刘冰琦 | D28: 3天 | E28: 3 | I28: =E28+F28 -> 3
A29: 27 | B29: 46119 | C29: 梁伟丽 | D29: 3天 | E29: 3 | I29: =E29+F29 -> 3
I30: =E30+F30 -> 0
E31: =SUM(E3:E30) -> 48 | F31: =SUM(F3:F30) -> 33 | I31: =E31+F31 -> 81

Sheet 4.9
A1: 浛洸镇第二小学教师鲜奶领奶表
A2: 序号 | B2: 配送日期 | C2: 职工姓名 | D2: 配送天数 | E2: 鲜 | F2: 酸 | G2: 备注
A3: 1 | B3: 46121 | C3: 冯敏婷 | D3: 4天 | E3: 4 | I3: =E3+F3 -> 4
A4: 2 | B4: 46121 | C4: 张美婷1 | D4: 4天 | E4: 4 | I4: =E4+F4 -> 4
A5: 3 | B5: 46121 | C5: 张美婷2 | D5: 4天 | F5: 4 | I5: =E5+F5 -> 4
A6: 4 | B6: 46121 | C6: 张美婷3 | D6: 4天 | E6: 4 | I6: =E6+F6 -> 4
A7: 5 | B7: 46121 | C7: 张美婷4 | D7: 4天 | F7: 4 | I7: =E7+F7 -> 4
A8: 6 | B8: 46121 | C8: 张美婷5 | D8: 4天 | F8: 4 | I8: =E8+F8 -> 4
A9: 7 | B9: 46121 | C9: 彭海玲 | D9: 4天 | F9: 4 | I9: =E9+F9 -> 4
A10: 8 | B10: 46121 | C10: 陈炜宇 | D10: 4天 | E10: 4 | I10: =E10+F10 -> 4
A11: 9 | B11: 46121 | C11: 赖翠美 | D11: 4天 | F11: 4 | I11: =E11+F11 -> 4
A12: 10 | B12: 46121 | C12: 陈房军 | D12: 4天 | F12: 4 | I12: =E12+F12 -> 4
A13: 11 | B13: 46121 | C13: 杨桃 | D13: 4天 | E13: 2 | F13: 2 | I13: =E13+F13 -> 4
A14: 12 | B14: 46121 | C14: 谢秀云 | D14: 4天 | E14: 2 | F14: 2 | I14: =E14+F14 -> 4
A15: 13 | B15: 46121 | C15: 李梓航 | D15: 4天 | E15: 2 | F15: 2 | I15: =E15+F15 -> 4
A16: 14 | B16: 46121 | C16: 郭婷婷 | D16: 4天 | F16: 4 | I16: =E16+F16 -> 4
A17: 15 | B17: 46121 | C17: 张桂兰 | D17: 4天 | E17: 4 | I17: =E17+F17 -> 4
A18: 16 | B18: 46121 | C18: 陈勇强 | D18: 4天 | E18: 2 | F18: 2 | I18: =E18+F18 -> 4
A19: 17 | B19: 46121 | C19: 谢金红1 | D19: 4天 | E19: 4 | I19: =E19+F19 -> 4
A20: 18 | B20: 46121 | C20: 谢金红2 | D20: 4天 | E20: 4 | I20: =E20+F20 -> 4
A21: 19 | B21: 46121 | C21: 陈石胡 | D21: 4天 | E21: 4 | I21: =E21+F21 -> 4
A22: 20 | B22: 46121 | C22: 赖兰香 | D22: 4天 | E22: 2 | F22: 2 | I22: =E22+F22 -> 4
A23: 21 | B23: 46121 | C23: 郝秀丽 | D23: 4天 | E23: 2 | F23: 2 | I23: =E23+F23 -> 4
A24: 22 | B24: 46121 | C24: 朱玉琼 | D24: 4天 | E24: 4 | I24: =E24+F24 -> 4
A25: 23 | B25: 46121 | C25: 谢秀群 | D25: 4天 | F25: 4 | I25: =E25+F25 -> 4
A26: 24 | B26: 46121 | C26: 付玉芬1 | D26: 4天 | E26: 4 | I26: =E26+F26 -> 4
A27: 25 | B27: 46121 | C27: 付玉芬2 | D27: 4天 | F27: 4 | I27: =E27+F27 -> 4
A28: 26 | B28: 46121 | C28: 刘冰琦 | D28: 4天 | E28: 4 | I28: =E28+F28 -> 4
A29: 27 | B29: 46121 | C29: 梁伟丽 | D29: 4天 | E29: 4 | I29: =E29+F29 -> 4
I30: =E30+F30 -> 0
E31: =SUM(E3:E30) -> 60 | F31: =SUM(F3:F30) -> 48 | I31: =E31+F31 -> 108

Sheet 4.13
A1: 浛洸镇第二小学教师鲜奶领奶表
A2: 序号 | B2: 配送日期 | C2: 职工姓名 | D2: 配送天数 | E2: 鲜 | F2: 酸 | G2: 备注
A3: 1 | B3: 46125 | C3: 冯敏婷 | D3: 3天 | E3: 3 | I3: =E3+F3 -> 3
A4: 2 | B4: 46125 | C4: 张美婷1 | D4: 3天 | E4: 3 | I4: =E4+F4 -> 3
A5: 3 | B5: 46125 | C5: 张美婷2 | D5: 3天 | F5: 3 | I5: =E5+F5 -> 3
A6: 4 | B6: 46125 | C6: 张美婷3 | D6: 3天 | E6: 3 | I6: =E6+F6 -> 3
A7: 5 | B7: 46125 | C7: 张美婷4 | D7: 3天 | F7: 3 | I7: =E7+F7 -> 3
A8: 6 | B8: 46125 | C8: 张美婷5 | D8: 3天 | F8: 3 | I8: =E8+F8 -> 3
A9: 7 | B9: 46125 | C9: 彭海玲 | D9: 3天 | F9: 3 | I9: =E9+F9 -> 3
A10: 8 | B10: 46125 | C10: 陈炜宇 | D10: 3天 | E10: 3 | I10: =E10+F10 -> 3
A11: 9 | B11: 46125 | C11: 赖翠美 | D11: 3天 | F11: 3 | I11: =E11+F11 -> 3
A12: 10 | B12: 46125 | C12: 陈房军 | D12: 3天 | F12: 3 | I12: =E12+F12 -> 3
A13: 11 | B13: 46125 | C13: 杨桃 | D13: 3天 | E13: 2 | F13: 1 | I13: =E13+F13 -> 3
A14: 12 | B14: 46125 | C14: 谢秀云 | D14: 3天 | E14: 2 | F14: 1 | I14: =E14+F14 -> 3
A15: 13 | B15: 46125 | C15: 李梓航 | D15: 3天 | E15: 2 | F15: 1 | I15: =E15+F15 -> 3
A16: 14 | B16: 46125 | C16: 郭婷婷 | D16: 3天 | F16: 3 | I16: =E16+F16 -> 3
A17: 15 | B17: 46125 | C17: 张桂兰 | D17: 3天 | E17: 3 | I17: =E17+F17 -> 3
A18: 16 | B18: 46125 | C18: 陈勇强 | D18: 3天 | E18: 2 | F18: 1 | I18: =E18+F18 -> 3
A19: 17 | B19: 46125 | C19: 谢金红1 | D19: 3天 | E19: 3 | I19: =E19+F19 -> 3
A20: 18 | B20: 46125 | C20: 谢金红2 | D20: 3天 | E20: 3 | I20: =E20+F20 -> 3
A21: 19 | B21: 46125 | C21: 陈石胡 | D21: 3天 | E21: 3 | I21: =E21+F21 -> 3
A22: 20 | B22: 46125 | C22: 赖兰香 | D22: 3天 | E22: 2 | F22: 1 | I22: =E22+F22 -> 3
A23: 21 | B23: 46125 | C23: 郝秀丽 | D23: 3天 | E23: 2 | F23: 1 | I23: =E23+F23 -> 3
A24: 22 | B24: 46125 | C24: 朱玉琼 | D24: 3天 | E24: 3 | I24: =E24+F24 -> 3
A25: 23 | B25: 46125 | C25: 谢秀群 | D25: 3天 | F25: 3 | I25: =E25+F25 -> 3
A26: 24 | B26: 46125 | C26: 付玉芬1 | D26: 3天 | E26: 3 | I26: =E26+F26 -> 3
A27: 25 | B27: 46125 | C27: 付玉芬2 | D27: 3天 | F27: 3 | I27: =E27+F27 -> 3
A28: 26 | B28: 46125 | C28: 刘冰琦 | D28: 3天 | E28: 3 | I28: =E28+F28 -> 3
A29: 27 | B29: 46125 | C29: 梁伟丽 | D29: 3天 | E29: 3 | I29: =E29+F29 -> 3
I30: =E30+F30 -> 0
E31: =SUM(E3:E30) -> 48 | F31: =SUM(F3:F30) -> 33 | I31: =E31+F31 -> 81

Sheet 4.16
A1: 浛洸镇第二小学教师鲜奶领奶表
A2: 序号 | B2: 配送日期 | C2: 职工姓名 | D2: 配送天数 | E2: 鲜 | F2: 酸 | G2: 备注
A3: 1 | B3: 46128 | C3: 冯敏婷 | D3: 4天 | E3: 4 | I3: =E3+F3 -> 4
A4: 2 | B4: 46128 | C4: 张美婷1 | D4: 4天 | E4: 4 | I4: =E4+F4 -> 4
A5: 3 | B5: 46128 | C5: 张美婷2 | D5: 4天 | F5: 4 | I5: =E5+F5 -> 4
A6: 4 | B6: 46128 | C6: 张美婷3 | D6: 4天 | E6: 4 | I6: =E6+F6 -> 4
A7: 5 | B7: 46128 | C7: 张美婷4 | D7: 4天 | F7: 4 | I7: =E7+F7 -> 4
A8: 6 | B8: 46128 | C8: 张美婷5 | D8: 4天 | F8: 4 | I8: =E8+F8 -> 4
A9: 7 | B9: 46128 | C9: 彭海玲 | D9: 4天 | F9: 4 | I9: =E9+F9 -> 4
A10: 8 | B10: 46128 | C10: 陈炜宇 | D10: 4天 | E10: 4 | I10: =E10+F10 -> 4
A11: 9 | B11: 46128 | C11: 赖翠美 | D11: 4天 | F11: 4 | I11: =E11+F11 -> 4
A12: 10 | B12: 46128 | C12: 陈房军 | D12: 4天 | F12: 4 | I12: =E12+F12 -> 4
A13: 11 | B13: 46128 | C13: 杨桃 | D13: 4天 | E13: 2 | F13: 2 | I13: =E13+F13 -> 4
A14: 12 | B14: 46128 | C14: 谢秀云 | D14: 4天 | E14: 2 | F14: 2 | I14: =E14+F14 -> 4
A15: 13 | B15: 46128 | C15: 李梓航 | D15: 4天 | E15: 2 | F15: 2 | I15: =E15+F15 -> 4
A16: 14 | B16: 46128 | C16: 郭婷婷 | D16: 4天 | F16: 4 | I16: =E16+F16 -> 4
A17: 15 | B17: 46128 | C17: 张桂兰 | D17: 4天 | E17: 4 | I17: =E17+F17 -> 4
A18: 16 | B18: 46128 | C18: 陈勇强 | D18: 4天 | E18: 2 | F18: 2 | I18: =E18+F18 -> 4
A19: 17 | B19: 46128 | C19: 谢金红1 | D19: 4天 | E19: 4 | I19: =E19+F19 -> 4
A20: 18 | B20: 46128 | C20: 谢金红2 | D20: 4天 | E20: 4 | I20: =E20+F20 -> 4
A21: 19 | B21: 46128 | C21: 陈石胡 | D21: 4天 | E21: 4 | I21: =E21+F21 -> 4
A22: 20 | B22: 46128 | C22: 赖兰香 | D22: 4天 | E22: 2 | F22: 2 | I22: =E22+F22 -> 4
A23: 21 | B23: 46128 | C23: 郝秀丽 | D23: 4天 | E23: 2 | F23: 2 | I23: =E23+F23 -> 4
A24: 22 | B24: 46128 | C24: 朱玉琼 | D24: 4天 | E24: 4 | I24: =E24+F24 -> 4
A25: 23 | B25: 46128 | C25: 谢秀群 | D25: 4天 | F25: 4 | I25: =E25+F25 -> 4
A26: 24 | B26: 46128 | C26: 付玉芬1 | D26: 4天 | E26: 4 | I26: =E26+F26 -> 4
A27: 25 | B27: 46128 | C27: 付玉芬2 | D27: 4天 | F27: 4 | I27: =E27+F27 -> 4
A28: 26 | B28: 46128 | C28: 刘冰琦 | D28: 4天 | E28: 4 | I28: =E28+F28 -> 4
A29: 27 | B29: 46128 | C29: 梁伟丽 | D29: 4天 | E29: 4 | I29: =E29+F29 -> 4
I30: =E30+F30 -> 0
E31: =SUM(E3:E30) -> 60 | F31: =SUM(F3:F30) -> 48 | I31: =E31+F31 -> 108

Sheet 4.20
A1: 浛洸镇第二小学教师鲜奶领奶表
A2: 序号 | B2: 配送日期 | C2: 职工姓名 | D2: 配送天数 | E2: 鲜 | F2: 酸 | G2: 备注
A3: 1 | B3: 46132 | C3: 冯敏婷 | D3: 3天 | E3: 3 | I3: =E3+F3 -> 3
A4: 2 | B4: 46132 | C4: 张美婷1 | D4: 3天 | E4: 3 | I4: =E4+F4 -> 3
A5: 3 | B5: 46132 | C5: 张美婷2 | D5: 3天 | F5: 3 | I5: =E5+F5 -> 3
A6: 4 | B6: 46132 | C6: 张美婷3 | D6: 3天 | E6: 3 | I6: =E6+F6 -> 3
A7: 5 | B7: 46132 | C7: 张美婷4 | D7: 3天 | F7: 3 | I7: =E7+F7 -> 3
A8: 6 | B8: 46132 | C8: 张美婷5 | D8: 3天 | F8: 3 | I8: =E8+F8 -> 3
A9: 7 | B9: 46132 | C9: 彭海玲 | D9: 3天 | F9: 3 | I9: =E9+F9 -> 3
A10: 8 | B10: 46132 | C10: 陈炜宇 | D10: 3天 | E10: 3 | I10: =E10+F10 -> 3
A11: 9 | B11: 46132 | C11: 赖翠美 | D11: 3天 | F11: 3 | I11: =E11+F11 -> 3
A12: 10 | B12: 46132 | C12: 陈房军 | D12: 3天 | F12: 3 | I12: =E12+F12 -> 3
A13: 11 | B13: 46132 | C13: 杨桃 | D13: 3天 | E13: 2 | F13: 1 | I13: =E13+F13 -> 3
A14: 12 | B14: 46132 | C14: 谢秀云 | D14: 3天 | E14: 2 | F14: 1 | I14: =E14+F14 -> 3
A15: 13 | B15: 46132 | C15: 李梓航 | D15: 3天 | E15: 2 | F15: 1 | I15: =E15+F15 -> 3
A16: 14 | B16: 46132 | C16: 郭婷婷 | D16: 3天 | F16: 3 | I16: =E16+F16 -> 3
A17: 15 | B17: 46132 | C17: 张桂兰 | D17: 3天 | E17: 3 | I17: =E17+F17 -> 3
A18: 16 | B18: 46132 | C18: 陈勇强 | D18: 3天 | E18: 2 | F18: 1 | I18: =E18+F18 -> 3
A19: 17 | B19: 46132 | C19: 谢金红1 | D19: 3天 | E19: 3 | I19: =E19+F19 -> 3
A20: 18 | B20: 46132 | C20: 谢金红2 | D20: 3天 | E20: 3 | I20: =E20+F20 -> 3
A21: 19 | B21: 46132 | C21: 陈石胡 | D21: 3天 | E21: 3 | I21: =E21+F21 -> 3
A22: 20 | B22: 46132 | C22: 赖兰香 | D22: 3天 | E22: 2 | F22: 1 | I22: =E22+F22 -> 3
A23: 21 | B23: 46132 | C23: 郝秀丽 | D23: 3天 | E23: 2 | F23: 1 | I23: =E23+F23 -> 3
A24: 22 | B24: 46132 | C24: 朱玉琼 | D24: 3天 | E24: 3 | I24: =E24+F24 -> 3
A25: 23 | B25: 46132 | C25: 谢秀群 | D25: 3天 | F25: 3 | I25: =E25+F25 -> 3
A26: 24 | B26: 46132 | C26: 付玉芬1 | D26: 3天 | E26: 3 | I26: =E26+F26 -> 3
A27: 25 | B27: 46132 | C27: 付玉芬2 | D27: 3天 | F27: 3 | I27: =E27+F27 -> 3
A28: 26 | B28: 46132 | C28: 刘冰琦 | D28: 3天 | E28: 3 | I28: =E28+F28 -> 3
A29: 27 | B29: 46132 | C29: 梁伟丽 | D29: 3天 | E29: 3 | I29: =E29+F29 -> 3
I30: =E30+F30 -> 0
E31: =SUM(E3:E30) -> 48 | F31: =SUM(F3:F30) -> 33 | I31: =E31+F31 -> 81

Sheet 4.23
A1: 浛洸镇第二小学教师鲜奶领奶表
A2: 序号 | B2: 配送日期 | C2: 职工姓名 | D2: 配送天数 | E2: 鲜 | F2: 酸 | G2: 备注
A3: 1 | B3: 46135 | C3: 冯敏婷 | D3: 4天 | E3: 4 | I3: =E3+F3 -> 4
A4: 2 | B4: 46135 | C4: 张美婷1 | D4: 4天 | E4: 4 | I4: =E4+F4 -> 4
A5: 3 | B5: 46135 | C5: 张美婷2 | D5: 4天 | F5: 4 | I5: =E5+F5 -> 4
A6: 4 | B6: 46135 | C6: 张美婷3 | D6: 4天 | E6: 4 | I6: =E6+F6 -> 4
A7: 5 | B7: 46135 | C7: 张美婷4 | D7: 4天 | F7: 4 | I7: =E7+F7 -> 4
A8: 6 | B8: 46135 | C8: 张美婷5 | D8: 4天 | F8: 4 | I8: =E8+F8 -> 4
A9: 7 | B9: 46135 | C9: 彭海玲 | D9: 4天 | F9: 4 | I9: =E9+F9 -> 4
A10: 8 | B10: 46135 | C10: 陈炜宇 | D10: 4天 | E10: 4 | I10: =E10+F10 -> 4
A11: 9 | B11: 46135 | C11: 赖翠美 | D11: 4天 | F11: 4 | I11: =E11+F11 -> 4
A12: 10 | B12: 46135 | C12: 陈房军 | D12: 4天 | F12: 4 | I12: =E12+F12 -> 4
A13: 11 | B13: 46135 | C13: 杨桃 | D13: 4天 | E13: 2 | F13: 2 | I13: =E13+F13 -> 4
A14: 12 | B14: 46135 | C14: 谢秀云 | D14: 4天 | E14: 2 | F14: 2 | I14: =E14+F14 -> 4
A15: 13 | B15: 46135 | C15: 李梓航 | D15: 4天 | E15: 2 | F15: 2 | I15: =E15+F15 -> 4
A16: 14 | B16: 46135 | C16: 郭婷婷 | D16: 4天 | F16: 4 | I16: =E16+F16 -> 4
A17: 15 | B17: 46135 | C17: 张桂兰 | D17: 4天 | E17: 4 | I17: =E17+F17 -> 4
A18: 16 | B18: 46135 | C18: 陈勇强 | D18: 4天 | E18: 2 | F18: 2 | I18: =E18+F18 -> 4
A19: 17 | B19: 46135 | C19: 谢金红1 | D19: 4天 | E19: 4 | I19: =E19+F19 -> 4
A20: 18 | B20: 46135 | C20: 谢金红2 | D20: 4天 | E20: 4 | I20: =E20+F20 -> 4
A21: 19 | B21: 46135 | C21: 陈石胡 | D21: 4天 | E21: 4 | I21: =E21+F21 -> 4
A22: 20 | B22: 46135 | C22: 赖兰香 | D22: 4天 | E22: 2 | F22: 2 | I22: =E22+F22 -> 4
A23: 21 | B23: 46135 | C23: 郝秀丽 | D23: 4天 | E23: 2 | F23: 2 | I23: =E23+F23 -> 4
A24: 22 | B24: 46135 | C24: 朱玉琼 | D24: 4天 | E24: 4 | I24: =E24+F24 -> 4
A25: 23 | B25: 46135 | C25: 谢秀群 | D25: 4天 | F25: 4 | I25: =E25+F25 -> 4
A26: 24 | B26: 46135 | C26: 付玉芬1 | D26: 4天 | E26: 4 | I26: =E26+F26 -> 4
A27: 25 | B27: 46135 | C27: 付玉芬2 | D27: 4天 | F27: 4 | I27: =E27+F27 -> 4
A28: 26 | B28: 46135 | C28: 刘冰琦 | D28: 4天 | E28: 4 | I28: =E28+F28 -> 4
A29: 27 | B29: 46135 | C29: 梁伟丽 | D29: 4天 | E29: 4 | I29: =E29+F29 -> 4
I30: =E30+F30 -> 0
E31: =SUM(E3:E30) -> 60 | F31: =SUM(F3:F30) -> 48 | I31: =E31+F31 -> 108
